{"errorMessage":"An error occurred (500) when calling the PutRecord operation (reached max retries: 4): ","errorType":"ClientError","stackTrace":["  File \"/var/task/producer_lambda.py\", line 59, in producer_handler\n    response = put_record(client, stream_name, data)\n","  File \"/var/task/producer_lambda.py\", line 29, in put_record\n    response = client.put_record(\n","  File \"/var/task/botocore/client.py\", line 415, in _api_call\n    return self._make_api_call(operation_name, kwargs)\n","  File \"/var/task/botocore/client.py\", line 745, in _make_api_call\n    raise error_class(parsed_response, operation_name)\n"]}
